<mujocoinclude>
  <!--
  Usage:

  <mujoco>
  	<compiler meshdir="../meshes/sawyer" ...></compiler>
  	<include file="shared_config.xml"></include>
      (new stuff)
  	<worldbody>
  		<include file="sawyer_xyz_base.xml"></include>
          (new stuff)
  	</worldbody>
  </mujoco>
  -->

      <camera pos="0 0.5 1.5" name="topview" />
      <camera name="corner" mode="fixed" pos="-1.1 -0.4 0.6" xyaxes="-1 1 0 -0.2 -0.2 -1"/>
      <camera name="corner2" fovy="60" mode="fixed" pos="1.3 -0.2 1.1" euler="3.9 2.3 0.6"/>
      <camera name="corner3" fovy="45" mode="fixed" pos="0.9 0 1.5" euler="3.5 2.7 1"/>
      <!--<geom name="floor" type="plane" pos="0 0 -.9" size="10 10 10"-->
            <!--rgba="0 0 0 1" contype="15" conaffinity="15" />-->
      <!--<geom name="tableTop" type="box" pos="0 0.6 -0.45" size="0.4 0.2 0.45"
            rgba=".6 .6 .5 1" contype="15" conaffinity="15" />-->
      <!-- <geom name="tableTop" type="plane" pos="0 0.6 0" size="0.4 0.4 0.5" -->
            <!-- rgba=".6 .6 .5 1" contype="1" conaffinity="1" friction="2 0.1 0.002" material="light_wood_v3"/> -->

      <body name="link_base" childclass="lite6">
      <inertial pos="-0.00829545 3.26357e-05 0.0631195" mass="1.65394" diaginertia="0 0 0"/>
      <geom class="visual" mesh="link_base"/>
      <geom name="link_base_c" class="collision" mesh="link_base_c"/>
      <body name="link1" pos="0 0 0.2435">
        <inertial pos="-0.00036 0.04195 -0.0025" quat="0.608059 0.792349 -0.0438707 0.0228718" mass="1.411"
          diaginertia="0.00145276 0.00135275 0.000853355"/>
        <joint name="joint1" range="-6.28319 6.28319"/>
        <geom class="visual" mesh="link1"/>
        <geom name="link1_c" class="collision" mesh="link1_c"/>
        <body name="link2" quat="-1 1 1 1">
          <inertial pos="0.179 0 0.0584" quat="0.417561 0.571619 0.569585 0.417693" mass="1.34"
            diaginertia="0.00560971 0.0052152 0.00122018"/>
          <joint name="joint2" range="-2.61799 2.61799"/>
          <geom class="visual" mesh="link2"/>
          <geom name="link2_c" class="collision" mesh="link2_c"/>
          <body name="link3" pos="0.2002 0 0" quat="-2.59734e-06 -0.707105 -0.707108 -2.59735e-06">
            <inertial pos="0.072 -0.0357 -0.001" quat="0.128259 0.662963 -0.167256 0.71837" mass="0.953"
              diaginertia="0.0018521 0.00175546 0.000703807"/>
            <joint name="joint3" range="-0.061087 5.23599"/>
            <geom class="visual" mesh="link3"/>
            <geom name="link3_c" class="collision" mesh="link3_c"/>
            <body name="link4" pos="0.087 -0.22761 0" quat="0.707105 0.707108 0 0">
              <inertial pos="-0.002 -0.0285 -0.0813" quat="0.975248 0.22109 0.00203498 -0.00262178" mass="1.284"
                diaginertia="0.00370503 0.00349091 0.00109586"/>
              <joint name="joint4" range="-6.28319 6.28319"/>
              <geom class="visual" mesh="link4"/>
              <geom name="link4_c" class="collision" mesh="link4_c"/>
              <body name="link5" quat="1 1 0 0">
                <inertial pos="0 0.01 0.0019" quat="0.71423 0.696388 -0.0531933 0.0456997" mass="0.804"
                  diaginertia="0.000567553 0.000529266 0.000507681"/>
                <joint name="joint5" range="-2.1642 2.1642"/>
                <geom class="visual" mesh="link5"/>
                <geom name="link5_c" class="collision" mesh="link5_c"/>
                <body name="link6" pos="0 0.0625 0" quat="1 -1 0 0">
                  <inertial pos="0 -0.00194 -0.0102" quat="-0.0376023 0.704057 0.0446838 0.707738" mass="0.13"
                    diaginertia="0.000148148 8.57757e-05 7.71412e-05"/>
                  <joint name="joint6" range="-6.28319 6.28319"/>
                  <geom class="visual" mesh="link6" material="silver"/>
                  <geom name="link6_c" class="collision" mesh="link6_c"/>
                  <site name="attachment_site"/>
                  <body name="gripper_body" pos="0 0 0" quat="1 0 0 0">
                    <inertial pos="0.0 0.0 0.026" quat="1 0 0 0" mass="0.26"
                      diaginertia="0.00016117 0.000118 0.00014455" />
                    <geom name="gripper_lite_body" class="visual" mesh="gripper_lite_body" material="white"/>
                    <geom name="gripper_lite_body_c" class="collision" mesh="gripper_lite_body_c"/>
                    <body name="gripper_left_finger" pos="0 0 0.054" quat="1 0 0 0">
                      <inertial pos="0.0 -0.005 0.01" quat="1 0 0 0" mass="0.024"
                        diaginertia="1.961e-6 2.274e-6 1.238e-6" />
                      <geom name="gripper_left_finger" mesh="gripper_lite_left_finger_narrow" material="black" condim="4" solimp="2 1 0.01" solref="0.01 1" friction="1 0.005 0.0001"/>
                      <joint name="gripper_left_finger" pos="0 0 0" axis="0 1 0" type="slide" limited="true" range="-0.0081 -1e-5" frictionloss="1" />
                    </body>
                    <body name="gripper_right_finger" pos="0 0 0.054" quat="1 0 0 0">
                      <inertial pos="0.0 0.005 0.01" quat="1 0 0 0" mass="0.024"
                        diaginertia="1.961e-6 2.274e-6 1.238e-6" />
                      <geom name="gripper_right_finger" mesh="gripper_lite_right_finger_narrow" material="black" condim="4" solimp="2 1 0.01" solref="0.01 1" friction="1 0.005 0.0001"/>
                      <joint name="gripper_right_finger" pos="0 0 0" axis="0 1 0" type="slide" limited="true" range="1e-5 0.0081" frictionloss="1" />
                    </body>
                                              <body name="hand" pos="0 0 0.12" quat="-1 0 1 0">
                                                  <camera name="behindGripper" mode="track" pos="0 0 -0.5" quat="0 1 0 0" fovy="60" />
                                                  <camera name="gripperPOV" mode="track" pos="0.04 -0.06 0" quat="-1 -1.3 0 0" fovy="90" />

                                                  <site name="endEffector" pos="0.04 0 0" size="0.01" rgba='1 1 1 0' />
                                                  <geom name="rail" type="box" pos="-0.05 0 0" density="7850" size="0.005 0.055 0.005"  rgba="0.5 0.5 0.5 1.0" condim="3" friction="2 0.1 0.002"   />

                                                  <!--IMPORTANT: For rougher contact with gripper, set higher friciton values for the other interacting objects -->
                                                  <body name="rightclaw" pos="0 -0.05 0" >

                                                      <geom class="base_col" name="rightclaw_it" condim="4" margin="0.001" type="box" user="0" pos="0 0 0" size="0.045 0.003 0.015"  rgba="1 1 1 1.0"   />

                                                      <joint name="r_close" pos="0 0 0" axis="0 1 0" range= "0 0.04" armature="100" damping="1000" limited="true"  type="slide"/>
                                                      <!-- <joint name="r_close" pos="0 0 0" axis="0 1 0" range= "0 0.03" armature="100" damping="1000" limited="true"  type="slide"/>  -->

                                                      <!-- <site name="rightEndEffector" pos="0.0 0.005 0" size="0.044 0.008 0.012" type='box' /> -->

                                                      <!-- <site name="rightEndEffector" pos="0.035 0 0" size="0.01" rgba="1.0 0.0 0.0 1.0"/> -->
                                                      <site name="rightEndEffector" pos="0.045 0 0" size="0.01" rgba="1.0 0.0 0.0 1.0"/>
                                                      <body name="rightpad" pos ="0 .003 0" >
                                                          <geom name="rightpad_geom" condim="4" margin="0.001" type="box" user="0" pos="0 0 0" size="0.045 0.003 0.015" rgba="1 1 1 1.0" solimp="0.95 0.99 0.01" solref="0.01 1" friction="2 0.1 0.002" contype="1" conaffinity="1" mass="1"/>
                                                      </body>

                                                  </body>

                                                  <body name="leftclaw" pos="0 0.05 0">
                                                      <geom class="base_col" name="leftclaw_it" condim="4" margin="0.001" type="box" user="0" pos="0 0 0" size="0.045 0.003 0.015"  rgba="0 1 1 1.0"  />
                                                      <joint name="l_close" pos="0 0 0" axis="0 1 0" range= "-0.03 0" armature="100" damping="1000" limited="true"  type="slide"/>
                                                      <!-- <site name="leftEndEffector" pos="0.0 -0.005 0" size="0.044 0.008 0.012" type='box' /> -->
                                                      <!-- <site name="leftEndEffector" pos="0.035 0 0" size="0.01" rgba="1.0 0.0 0.0 1.0"/> -->
                                                      <site name="leftEndEffector" pos="0.045 0 0" size="0.01" rgba="1.0 0.0 0.0 1.0"/>
                                                      <body name="leftpad" pos ="0 -.003 0" >
                                                          <geom name="leftpad_geom" condim="4" margin="0.001" type="box" user="0" pos="0 0 0" size="0.045 0.003 0.015" rgba="0 1 1 1.0" solimp="0.95 0.99 0.01" solref="0.01 1" friction="2 0.1 0.002"  contype="1" conaffinity="1" />
                                                      </body>

                                                  </body>
                                              </body>
  <!--  ================= END GRIPPER ================= /-->
                                          </body>
                                      </body>
                                  </body>
                                  <body name="right_l4_2" pos="0 0 0">
                                      <inertial pos="1e-08 1e-08 1e-08" quat="0.820473 0.339851 -0.17592 0.424708" mass="1e-08" diaginertia="1e-08 1e-08 1e-08" />
                                      <!-- <geom size="0.06" pos="0 0.01 0.26"
                                            rgba="0.2 0.2 0.2 0"
                                            contype="0"
                                            conaffinity="0"
                                      /> -->
                                  </body>
                              </body>
                          </body>
                          <body name="right_l2_2" pos="0 0 0">
                              <inertial pos="1e-08 1e-08 1e-08" quat="0.820473 0.339851 -0.17592 0.424708" mass="1e-08" diaginertia="1e-08 1e-08 1e-08" />
                              <!-- <geom size="0.06" pos="0 0 0.26" rgba="0.2 0.2 0.2 0"
                                    contype="0"
                                    conaffinity="0"
                              /> -->
                          </body>
                      </body>
                      <body name="right_l1_2" pos="0 0 0">
                          <inertial pos="1e-08 1e-08 1e-08" quat="0.820473 0.339851 -0.17592 0.424708" mass="1e-08" diaginertia="1e-08 1e-08 1e-08" />
                          <geom size="0.07 0.07" pos="0 0 0.035" type="cylinder" rgba="0.2 0.2 0.2 0"/>
                      </body>
                  </body>
              </body>

      <body mocap="true" name="mocap" pos="0 0 0">
          <!--For debugging, set the alpha to 1-->
          <!--<geom conaffinity="0" contype="0" pos="0 0 0" rgba="0.5 0.5 0.5 1" size="0.1 0.02 0.02" type="box"></geom>-->
          <geom conaffinity="0" contype="0" pos="0 0 0" rgba="0.0 0.5 0.5 0" size="0.01" type="sphere"></geom>
          <site name="mocap" pos="0 0 0" rgba="0.0 0.5 0.5 0" size="0.01" type="sphere"></site>
      </body>

</mujocoinclude>
